Workbook

Sheet понедельник 09.10 1 неделя
B1: понедельник 09.10
B3: Салат Битые огурцы по Китайски | C3: 120 | D3: 30
B4: Салат Блинный с Ветчиной | C4: 120 | D4: 25
B5: Оливье с ветчиной | C5: 120 | D5: 25
B6: Винегрет | C6: 120 | D6: 20
A7: ланч | B7: Салат из брокколи с морковью и огурцами | C7: 120 | D7: 200
A8: ланч | B8: * Салат Казань с курицей 120 | C8: 120 | D8: 300
A9: азия | B9: Ачик Чучук | C9: 120 | D9: 15
B10: Первые блюда
A11: ланч | B11: * Борщ Кубанский с кабачками и курицей | C11: 250 | D11: 200
A12: ланч | B12: Рассольник с фасолью | C12: 250 | D12: 250
B13: * Суп шурпа с говядиной и овощами по-узбекски 250 гр. | C13: 250 | D13: 35
B14: Основные блюда
A15: ланч | B15: Свинина по-строгановски | C15: 100 | D15: 250
A16: ланч | B16: Филе куриное с соусом карри | C16: 100 | D16: 200
B17: Говядина в кислосдадком соусе | C17: 75/50 | D17: 20
B18: Горбуша припущенная с лимоном | C18: 100 | D18: 30
B19: * Свинина Праздничная 100 гр.
B20: *Котлета по киевски | C20: 100 | D20: 35
B21: Филе куриное на гриле | C21: 100 | D21: 20
A22: азия | B22: Плов с курицей | C22: 250 | D22: 30
B23: Гарниры
A24: ланч | B24: Рис припущенный | C24: 150 | D24: 150
A25: ланч | B25: Пюре картофельное | C25: 150 | D25: 250
B26: Булгур с овощами | C26: 150 | D26: 25
B27: ФАСОЛЬ СТРУЧКОВАЯ с овощами | C27: 150 | D27: 30
B28: Картофель айдахо | C28: 150 | D28: 30
B29: Макароны отварные | C29: 150 | D29: 100
B30: Овощи гриль | C30: 150 | D30: 30
B31: завтрак
B32: *Каша молочная рисовая | C32: 200 | D32: 20
B33: Каша овсяная с яблоком постная | C33: 200 | D33: 20
B34: Кесадилья с ветчиной и овощами | C34: 100 | D34: 10
B35: глазунья из 2 яиц | C35: 80 | D35: 15
B36: яйцо отварное | C36: 1шт | D36: 10
B37: сосиска отварная | C37: 1 шт | D37: 10
B38: Сырники | D38: 10
B39: Сарделька отварная | C39: 100 | D39: 5
B40: * Запеканка из творога с курагой | C40: 100 | D40: 10
B41: *Драники картофельные с грибами 100 гр | C41: 100 | D41: 15
...

Sheet вторник 10.10 1 неделя 
B1: ВТОРНИК 10.10 | C1: выход
B2: Закуски и салаты
B3: Салат из свеклы с черносливом | C3: 120 | D3: 20
B4: * Салат Азия 120 гр. | C4: 120 | D4: 25 | E4: дигустация
B5: * Салат Чика с курицей,черносливом и огурцом 120гр | C5: 120 | D5: 25
B6: Салат Невеста | C6: 120 | D6: 25
A7: Ланч | B7: Салат Сельдь под шубой (заменена на мимозу) | C7: 120 | D7: 300 | E7: дигустация
A8: Ланч | B8: Салат из китайской капусты с овощами | C8: 120 | D8: 200 | E8: дигустация
A9: азия | B9: Салат из помидоров с красным луком | D9: 30
B10: Первые блюда
B11: Суп Гороховый с копченостями 250 гр. | C11: 250 | D11: 30 | E11: дигустация
A12: Ланч | B12: Суп-лапша куриный | C12: 250/20 | D12: 250 | E12: дигустация
A13: Ланч | B13: Суп-пюре сырный 250/10гр | C13: 250/10 | D13: 250 | E13: дигустация
B16: Основные блюда
A17: ланч | B17: Люля кебаб из курицы с острым соусом | C17: 100/10 | D17: 250 | E17: дигустация
A18: ланч | B18: Свинина в кисло-сладком соусе | C18: 75/30 | D18: 250 | E18: дигустация
B19: Курица барбекю с кунжутом | C19: 100 | D19: 25
B20: Гуляш по-Венгерски из говядины | C20: 75/50 | D20: 20
B21: Филе куриное запеченное с овощами и сыром моцарела | C21: 100 | D21: 25
B22: Котлета Обжорка | C22: 100 | D22: 20 | E22: дигустация
B23: Филе горбуши припущенное с овощами | C23: 100 | D23: 25
A24: АЗИЯ | B24: СОБА С КУРИЦЕЙ | C24: 250 | D24: 40
B25: Гарниры
B27: Овощи Гриль | C27: 150 | D27: 35
A28: Ланч | B28: Каша гречневая рассыпчатая | C28: 150 | D28: 250
A29: Ланч | B29: Капуста тушеная | C29: 150 | D29: 250 | E29: дигустация
B30: Макароны с томато и зеленью | C30: 150 | D30: 50 | E30: дигустация
B31: * Рис по-вьетнамски 150 гр. | C31: 150 | D31: 20 | E31: дигустация
B32: Кус-кус с овощами | C32: 150 | D32: 20
B33: Каша перловая с овощами | C33: 150 | D33: 20
B34: * Булгур по-Купечески 150 гр. | C34: 150 | D34: 20
B35: Завтраки
B36: *Каша молочная геркулесовая | D36: 15
B37: Каша рисовая с курагой молочная | D37: 5 | E37: фасуем в миски
B38: * Каша ячневая молочная с цукатами | D38: 5 | E38: фасуем в миски
B39: Каша овсянная молочная с тыквой | D39: 5 | E39: фасуем в миски
B40: *Каша постная ячневая с ягодами | D40: 15
B41: *Сырники из творога 100 гр | D41: 10
B42: *Сыр твердый 15 г | D42: 10
B43: Яйцо отварное | D43: 5
...

Sheet среда 11.10 1 неделя
B1: среда 11/10
B2: Закуски и салаты
A3: ланч | B3: =[1]Лист1!$B$1 -> Закуска свекольная с огурцом и яйцом | C3: 120 | D3: 150
A4: ланч | B4: =[1]Лист1!B2 -> Салат Шанхай с курицей | C4: =[1]Лист1!C2 -> 120 | D4: 300
B5: Салат Белый лебедь | C5: 120 | D5: 30
B6: * Салат деревенский со свежими овощами и сметаной 120 гр. | C6: 120 | D6: 30
B7: Салат Нежность | C7: 120 | D7: 30
A8: АЗИЯ | B8: Салат домашний по-грузински со свежими овощами | C8: 120 | D8: 40
B9: Первые блюда
B11: * Суп-пюре из тыквы 250 гр. | C11: 250 | D11: 30
A12: ланч | B12: =[1]Лист1!B3 -> Щи из квашеной капусты с индейкой | C12: =[1]Лист1!C3 -> 250 | D12: 250
A13: ланч | B13: =[1]Лист1!B4 -> Суп минестроне с фасолью | C13: =[1]Лист1!C4 -> 75 | D13: 250
B16: Основные блюда
A17: ланч | B17: Бризоль из курицы ( меняем на чахохбили) | C17: =[1]Лист1!C5 -> 100 | D17: 230
A18: ланч | B18: Суфле из печени | C18: 100 | D18: 50
A19: ланч | B19: =[1]Лист1!B6 -> Горбуша жареная в яйце | C19: =[1]Лист1!C6 -> 90 | D19: 210
B20: Горбуша паровая с лимоном | C20: 100 | D20: 25
B21: курица отварная | C21: 150 | D21: 25
B22: говядина отварная 50гр | C22: 50 | D22: 25
B23: филе куринное гриль | C23: 100 | D23: 25
B24: Бифштекс на гриле с сыром | C24: 100 | D24: 25
B25: свинина нежная | C25: 100 | D25: 25
A26: АЗИЯ | B26: плов из свинины | C26: 250 | D26: 35
B27: Гарниры
A28: ланч | B28: =[1]Лист1!B7 -> Картофель жареный | C28: 150 | D28: 250
A29: ланч | B29: =[1]Лист1!B8 -> Спагетти отварные | C29: 150 | D29: 250
B30: Овощной гарнир Фитнес | C30: 150 | D30: 25
B31: Свекла тушеная со сметаной | C31: 150 | D31: 25
B32: Тыква запеченая | C32: 150 | D32: 25
B33: овощи припущенные | C33: 150 | D33: 15
B34: Овощи гриль | C34: 150 | D34: 25
B35: Завтраки
B36: =[2]Лист1!A1 -> *Каша молочная пшенная | C36: =[2]Лист1!B1 -> 200 | D36: 25
B37: =[2]Лист1!A2 -> Каша рисовая с курагой молочная | C37: =[2]Лист1!B2 -> 200 | D37: 25
B38: =[2]Лист1!A3 -> Пудинг творожный с изюмом | C38: =[2]Лист1!B3 -> 100 | D38: 15
B39: =[2]Лист1!A5 -> Яйцо отварное | C39: =[2]Лист1!B5 -> 40 | D39: 10
B40: =[2]Лист1!A6 -> *Яичница глазунья 80 гр. | C40: =[2]Лист1!B6 -> 80 | D40: 20
B41: =[2]Лист1!A7 -> Омлет с зеленым горошком | C41: =[2]Лист1!B7 -> 100 | D41: 10
B42: =[2]Лист1!A8 -> Сосиски отварные | C42: =[2]Лист1!B8 -> 50 | D42: 15
B43: =[2]Лист1!A9 -> Сарделька отварная | C43: =[2]Лист1!B9 -> 100 | D43: 10
...

Sheet 12.10 четверг 1 неделя
A1: 1 неделя | B1: четверг 12.10
B2: Закуски и салаты
B3: Салат крабик | C3: 120 | D3: 30
B4: * Салат из стручковой фасоли с овощами 120 гр. | C4: 120 | D4: 20
B5: Сельдь с картофелем и луком | C5: 120 | D5: 20
B6: Салат из помидоров с брынзой и зеленой заправкой | C6: 120 | D6: 15
A7: ланч | B7: ='[3]Бизнес ланч '!D46 -> Салат с томатами и сельдереем | C7: ='[3]Бизнес ланч '!E46 -> 120 | D7: 170
A8: ланч | B8: ='[3]Бизнес ланч '!D47 -> Салат блинный с ветчиной | C8: ='[3]Бизнес ланч '!E47 -> 120 | D8: 300
A9: Азия | B9: * Салат Чап-ча с болгарским перцем 120 гр. | C9: 120 | D9: 40
B10: Первые блюда
B11: * Уха Ростовская с горбушей 250 гр. | C11: 250 | D11: 30
A12: ланч | B12: ='[3]Бизнес ланч '!D48 -> Гороховый с копченостями 250гр | C12: ='[3]Бизнес ланч '!E48 -> 250 | D12: 250
A13: ланч | B13: ='[3]Бизнес ланч '!D49 -> Суп-пюре Паприкаш | C13: ='[3]Бизнес ланч '!E49 -> 250 | D13: 200
B15: Основные блюда
B16: Филе куриное запеченное с ананасом | C16: 100 | D16: 30
B17: Говядина с грибами и овощами | C17: 100 | D17: 30
B18: Шашлык из свинины с овощами | C18: 100 | D18: 20
B19: * Куриные крылышки жаренные в арахисовом соусе по-сеульски 100 гр. | C19: 100 | D19: 35
B20: Горбуша запеченная с томатами | C20: 10 | D20: 30
A21: ланч | B21: Бифштекс по-Венгерски | C21: 100 | D21: 250
A22: ланч | B22: Курица жареная с аджикой | C22: 100 | D22: 250
A23: Азия | B23: Плов с курицей | C23: 250 | D23: 40
B24: Гарниры
B25: Картофель Айдахо | C25: 150 | D25: 45
B26: Тыква запеченная с розмарином | C26: 150 | D26: 30
B27: Овощи гриль | C27: 150 | D27: 30
B28: Рагу овощное | C28: 150 | D28: 30
A29: ланч | B29: Плов овощной | C29: 150 | D29: 250
A30: ланч | B30: Макароны отварные с соусом Песто | C30: 150 | D30: 250
B32: Завтраки
B33: Каша гречневая молочная | C33: 200 | D33: 20
B34: Каша ячневая постная с фруктами | C34: 200 | D34: 20
B35: *Сырники из творога 100 гр | C35: 100 | D35: 10
B36: Панкейки с бананом и ванильным соусом | C36: 100 | D36: 10
B37: * Оладьи из курицы с кукурузой и зеленью | C37: 100/30 гр. | D37: 15
B38: Яйцо отварное | C38: 40 | D38: 10
B39: Яичница глазунья с с осисками | C39: 100 | D39: 15
B40: Омлет с сыром | C40: 105 | D40: 20
B41: Сосиски отварные | C41: 50 | D41: 10
B42: Сарделька отварная | C42: 100 | D42: 10
...

Sheet 13.10 пятница 1 неделя
B1: пятница 13.10
B2: Закуски и салаты | D2: кол-во
B3: * Салат Коул Слоу 120 гр. | C3: 120 | D3: 20
B4: Оливье с колбасой | C4: 120 | D4: 20
B5: * Салат с ветчиной и овощами | C5: 120 | D5: 20
B6: * Салат из курицы с арахисом 120 гр. | C6: 120 | D6: 20
A7: Ланч | B7: Салат Овощной микс | C7: 120 | D7: 150
A8: ланч | B8: Салат Венеция с колбасой и огурцами | C8: 120 | D8: 300
A9: Азия | B9: помидоры с красным луком | C9: 120 | D9: 30
B10: Первые блюда
B12: Суп-пюре Восточный с баклажанами | C12: 250 | D12: 30
A13: Ланч | B13: Солянка домашняя из птицы | C13: 250 | D13: 250
A14: ланч | B14: Суп-лапша по-казачьи | C14: 250 | D14: 200
B16: Основные блюда
B17: Говядина в кисло-сладком соусе | C17: 100 | D17: 15
B18: филе куриное на гриле | C18: 100 | D18: 20
B19: Свинина с грибами | C19: 100 | D19: 15
B20: Филе кеты с помидорами под сыром | C20: 100 | D20: 15
B21: Окунь жареный | C21: 100 | D21: 5
A22: Ланч | B22: Печень по-строгановски | C22: 75/50 | D22: 200
A23: ланч | B23: Плескавица (должна быть курица под соусом тар-тар) | C23: 100 | D23: 300
A24: Азия | B24: Лагман жареный | D24: 30
B25: Гарниры
A26: ланч | B26: Каша гречневая рассыпчатая | C26: 150 | D26: 200
A27: ланч | B27: Рагу овощное | C27: 150 | D27: 250
B28: Спагетти отварные с сыром | C28: 150 | D28: 50
B29: Тыква запеченая | C29: 150 | D29: 25
B30: Картофель айдахо | C30: 150 | D30: 20
B31: * Капуста цветная жареная в сухарях 150 гр. | C31: 150 | D31: 20
B32: Завтраки
B33: *Каша молочная 3 злака | C33: 200 | D33: 20
B34: Каша рисовая постная с бананом | C34: 200 | D34: 20
B35: Сырники с морковью | C35: 100 | D35: 10
B36: Кесадилья с ветчиной | C36: 15 | D36: 5
B37: Яйцо отварное | C37: 40 | D37: 10
B38: *Яичница глазунья 80 гр. | C38: 80 | D38: 20
B39: Омлет с ветчиной | C39: 105 | D39: 25
B40: Сосиски отварные | C40: 50 | D40: 20
B41: Оладьи из кабачков | C41: 100 | D41: 10
B42: Бифштекс овощной | C42: 100 | D42: 10
...

Sheet понедельник  16.10 2 неделя
B1: понедельник 16.10
A3: ланч | B3: ='[3]Бизнес ланч '!I4 -> Салат Лагуна 120 гр.(Крабовые палочки,огурец св.,яйцо ,майонез,соль,зелень) | C3: ='[3]Бизнес ланч '!J4 -> 120 | D3: 300
A4: ланч | B4: ='[3]Бизнес ланч '!I5 -> * Салат Минский 120 гр.( Картофель жарен., капуста пекинская, ветчина, шампиньны ,лук репч., м/раст., зелень.) | C4: ='[3]Бизнес ланч '!J5 -> 120 | D4: 200
B5: Оливье с ветчиной | C5: 120 | D5: 25
B6: * Салат полянка 120 гр | C6: 120 | D6: 20
B7: Винегрет с сельдью | C7: 120 | D7: 15
B8: * Салат Цезарь с курицей 120 гр. | C8: 120 | D8: 15
B9: * Салат Греческий 120 гр. | C9: 120 | D9: 15
A10: азия | B10: * Салат Аджапсандал из запеченных овощей по-грузински | C10: 120 | D10: 40
B11: Первые блюда
B12: * Суп Венгерский с мясом | C12: 250 | D12: 30
A13: ланч | B13: ='[3]Бизнес ланч '!I6 -> Суп Осенний с курой | C13: 250 | D13: 250
A14: ланч | B14: ='[3]Бизнес ланч '!I7 -> * Похлебка по-суворовски 250 гр. | C14: ='[3]Бизнес ланч '!J7 -> 250 | D14: 250
B15: Основные блюда
B16: Бризоль из филе курицы | C16: 100 | D16: 20
B17: Говядина в кисло сладком соусе | C17: 75/50 | D17: 20
B18: Эскалоп запеченный с помидором и сыром | C18: 100 | D18: 15
B19: * Минтай жареный 100 гр. | C19: 100 | D19: 15
B20: Бифштекс рубленый с яйцом | C20: 100 | D20: 20
A21: ланч | B21: Горбуша по-Гречески | C21: 100 | D21: 200
A22: ланч | B22: Филе куриное под соусом Тар-тар | C22: 100 | D22: 300
A23: азия | B23: Плов с курицей | C23: 250 | D23: 40
B24: Гарниры
B25: Греча с грибами | C25: 150 | D25: 20
B26: Морковь пряная с травами | C26: 150 | D26: 15
B27: * Рис по-вьетнамски 150 гр. | C27: 150 | D27: 30
B28: Цветная капуста в сухарях | C28: 150 | D28: 25
B29: Овощи гриль | C29: 150 | D29: 25
A30: ланч | B30: Картофель запеченный с прованскими травами | C30: 150 | D30: 300
A31: ланч | B31: Спагетти с сыром | C31: 150 | D31: 200
B32: завтрак
B33: Каша рисовая молочная | C33: 200 | D33: 20
B34: Каша геркулесовая постная | C34: 200 | D34: 20
B35: *Сырники из творога 100 гр | C35: 80 | D35: 10
B36: кесадилья с овощами | C36: 1шт | D36: 10
B37: Яичница глазунья с помидорами | C37: 1 шт | D37: 20
B38: *Омлет натуральный 105 | D38: 15
B39: Сосиски отварные | D39: 15
B40: * Драники картофельные с сыром 100 гр. | D40: 15
B41: Оладьи с изюмом | D41: 20
...

Sheet вторник 17.10 2 неделя
B1: ВТОРНИК 17.10
B2: Закуски и салаты
B3: Салат из крабовых палочек с огурцами | C3: 120 | D3: 25
B4: * Салат Азия 120 гр. | C4: 120 | D4: 15
B5: Салат Ассорти из морской капусты | C5: 120 | D5: 25
B6: * Салат Звёздный 120 гр. | C6: 120 | D6: 20
A7: Ланч | B7: * Салат Чап-ча с болгарским перцем 120 гр. | C7: 120 | D7: 200
A8: Ланч | B8: * Салат колбасный 120 гр. | C8: 120 | D8: 300
A9: АЗИЯ | B9: * Салат домашний по-грузински со свежими овощами 120 гр. | D9: 20
B10: Первые блюда
B11: * Суп-крем из шампиньонов 250/10 гр. | C11: 250/10 | D11: 30
B12: * Борщ Сибирский с курой 250/20 гр. | C12: 250/20 | D12: 250
B13: * Суп Палиц 250 гр. | C13: 250 | D13: 200
B14: Основные блюда
B15: Филе Кеты в кляре | C15: 100 | D15: 15
B16: филе грудки гриль | C16: 110 | D16: 20
B17: Филе куриное запеченное с кабачками и сыром 100 гр. | C17: 100 | D17: 15
B18: Окунь жареный | C18: 100 | D18: 6
B19: Свинина по-французски | C19: 100 | D19: 10
B20: котлета по киевки | C20: 120 | D20: 30
A21: Ланч | B21: Курица жареная с аджикой | C21: 100 | D21: 300
A22: Ланч | B22: * Поджарка из свинины в томатном соусе 75/30 гр. | C22: 75/30 | D22: 200
A23: АЗИЯ | B23: лагман жареный | C23: 250 | D23: 40
B24: Гарниры
B25: каша гречневая томленная | C25: 150 | D25: 100
B26: Картофель жареный с грибами | C26: 150 | D26: 30
B27: Тыква запеченая с розмарином | C27: 150 | D27: 20
B28: Баклажаны в соевом соусе с чесноком и кунжутом | C28: 150 | D28: 10
A29: Ланч | B29: Рагу овощное | C29: 150 | D29: 200
A30: Ланч | B30: Рис отварной с карри | C30: 150 | D30: 300
B31: Завтраки
B32: *Каша молочная 3 злака | D32: 20
B33: Каша ячневая постная с фруктами | D33: 20
B34: Пудинг творожный с бананом | D34: 10
B35: Яйцо отварное | D35: 15
B36: *Яичница глазунья 80 гр. | D36: 20
B37: Омлет с зеленым луком | D37: 10
B38: Сосиски отварные | D38: 15
B39: * Кесадилья с ветчиной и овощами 100 гр. | D39: 10
B40: Зраза морковная с курагой | D40: 20
...

Sheet среда 18.10 2 неделя
B1: 18.10.2023 среда
B2: Закуски и салаты
B3: Салат Боярушка | C3: 120 | D3: 15
B4: Салат Белый лебедь | C4: 120 | D4: 20
B5: Салат Нежность | C5: 120 | D5: 20
B6: Салат Мимоза со скумбрией | C6: 120 | D6: 20
A7: ланч | B7: * Салат Журавушка 120 гр.(Капуста б/к, колбаса в/к, лук репчатый, майонез, специи ) | C7: 120 | D7: 250
A8: ланч | B8: Салат Фунчоза с курицей | C8: 120 | D8: 250
A9: АЗИЯ | B9: Салат из помидоров с красным луком | C9: 120 | D9: 40
B10: Первые блюда
B12: Суп Харчо с курицей | C12: 250
A13: ланч | B13: * Солянка по-Волгоградски 250 гр. | C13: 250 | D13: 300
A14: ланч | B14: * Суп-пюре из зелёного горошка 250/10 гр. | C14: 250/10 | D14: 150
B17: Основные блюда
A18: ланч | B18: * Филе куриное по-строгановски 75/50 гр. | C18: 75/50 | D18: 200
A19: ланч | B19: минтай жареный | C19: 100 | D19: 100
A20: ланч | B20: Котлета пожарская | C20: 100 | D20: 200
B21: Филе куриное в сырной корочке | C21: 100 | D21: 30
B22: Горбуша паровая с лимоном | C22: 100 | D22: 10
B23: Рулет мясной с зеленым луком и яйцом | C23: 100 | D23: 15
B24: Говядина с грибами и овощами | C24: 100 | D24: 10
B25: Шницель венский | C25: 100 | D25: 10
A26: АЗИЯ | B26: лагман жареный | C26: 250 | D26: 35
B27: Гарниры
A28: ланч | B28: Картофель отварной с зеленью | C28: 150 | D28: 300
A29: ланч | B29: Каша гречневая томленая | C29: 150 | D29: 150
B30: Кус-кус с овощами | C30: 150 | D30: 25
B31: * Кабачки со сметаной и чесноком 150 гр. | C31: 150 | D31: 15
B32: Макароны Рататуй | C32: 150 | D32: 100
B33: Тыква запеченая | C33: 150 | D33: 20
B34: Овощи гриль | C34: 150 | D34: 20
B35: Завтраки
B36: Каша рисовая молочная | C36: 200 | D36: 20
B37: Каша гречневая молочная | C37: 200 | D37: 15
B38: *Сырники из творога 100 гр | C38: 100 | D38: 10
B39: Яйцо отварное | C39: 40 | D39: 15
B40: Яичница глазунья с сыром | C40: 100 | D40: 25
B41: Омлет с грибами | C41: 105 | D41: 15
B42: Сосиски отварные | C42: 50 | D42: 15
B43: * Брускета с томатами и сыром 70гр. | C43: 100 | D43: 10
...

Sheet четверг 19.10 2 неделя
B1: четверг 19.10.2023
B2: Закуски и салаты | D2: кол-во
B3: Салат Вавилон | C3: 120 | D3: 35
B4: Салат Мадрид с курой копченой | C4: 120 | D4: 30
B5: * Салат Цезарь с курицей 120 гр. | C5: 120 | D5: 25
B6: * Салат Сибирский 120 гр. | C6: 120 | D6: 25
A7: ланч | B7: * Салат Несвижский 120 гр. | C7: 120 | D7: 300
A8: ланч | B8: * Салат АВС и горошек 120 гр. | C8: 120 | D8: 150
A9: Азия | B9: Салат с фунчозой | C9: 120 | D9: 30
B10: Первые блюда
B12: Суп Английский куриный с плавленым сыром | C12: 250 | D12: 30
A13: Ланч | B13: * Суп картофельный с фасолью и курицей 250 гр. | C13: 250 | D13: 200
A14: ланч | B14: Суп Шурпа с курицей 250 гр. | C14: 250 | D14: 300
B16: Основные блюда
B17: Котлеты по-Хлыновски | C17: 100 | D17: 20
B18: Шашлычок из курицы с перцем | C18: 100 | D18: 20
B19: запеканка картофельная с мясом | C19: 200 | D19: 35
B20: Филе куры гриль | C20: 100 | D20: 20
B21: Говядина с черносливом | C21: 75/50 | D21: 20
B22: Горбуша под овощами | C22: 125 | D22: 20
A23: Ланч | B23: * Жаркое по-Краснодарски 250 гр. | C23: 250 | D23: 200
A24: Ланч | B24: Суфле из печени | C24: 100 | D24: 100
A25: ланч | B25: Чахохбили из курицы | C25: 100 | D25: 250
A26: азия ланч | B26: соба с курицей | D26: 25
B27: Гарниры
A28: Ланч | B28: Каша гречневая рассыпчатая с луком | D28: 150
B29: Каша перловая с овощами | C29: 150 | D29: 25
B30: Макароны с томатом и базиликом | C30: 150 | D30: 50
B31: Капуста цветная в сухарях | C31: 150 | D31: 25
B32: Гратен Дофинуа | C32: 150 | D32: 40
B33: Кабачки, баклажаны жареные с овощами | C33: 150 | D33: 25
B34: Завтраки
B35: Каша манная молочная | C35: 200 | D35: 20
B36: Каша пшеничная постная | C36: 200 | D36: 20
B37: Запеканка творожная со смородиной | C37: 100 | D37: 10
B38: Яйцо отварное | C38: 40 | D38: 10
B39: *Яичница глазунья 80 гр. | C39: 80 | D39: 25
B40: *Омлет натуральный 105 | C40: 105 | D40: 15
B41: Сосиски отварные | C41: 50 | D41: 10
B42: Сарделька отварная | C42: 100 | D42: 10
...

Sheet 20.10 пятница 2 неделя
B1: пятница 20.10
B2: Закуски и салаты
B3: Салат Цезарь | C3: 120 | D3: 15
B4: * Салат блинный с ветчиной 120 гр. | C4: 120 | D4: 20
A5: ланч | B5: Морковь по-корейски с огурцом | C5: 120 | D5: 150
A6: ланч | B6: * Салат Вдохновение (курица, ветчина) 120 гр. | C6: 120 | D6: 350
B7: * Салат Витаминка с яблоком 120 гр. | C7: 120 | D7: 15
B8: Салат крабик | C8: 120 | D8: 20
A9: АЗИЯ | B9: ачик-чучук | C9: 120 | D9: 30
B10: Первые блюда
B11: Суп-пюре овощной с цветной капустой | C11: 250/10 | D11: 30
A12: ланч | B12: * Суп Венгерский с мясом 250 гр. | C12: 250 | D12: 350
A13: ланч | B13: * Бульон куриный с куриными фрикадельками 250 гр. | C13: 250 | D13: 150
B14: Основные блюда
A16: ланч | B16: Бифштекс Провансаль | C16: 75 | D16: 250
A17: ланч | B17: Бедро куриное под тар-тар | C17: 120 | D17: 250
B18: Люля-кебаб из говядины с луком маринованным | C18: 100/30 | D18: 30
B19: Горбуша запеченная по-Русски | C19: 100 | D19: 10
B20: Куриные крылышки барбекю | C20: 120 | D20: 15
B21: Окунь жареный | C21: 100 | D21: 5
B22: * Куриная грудка гриль 100 гр. | C22: 100 | D22: 30
A23: АЗИЯ | B23: плов со свининой | D23: 30
B24: Гарниры
B25: Картофель жареный с грибами | C25: 150 | D25: 25
B26: Тыква запеченная с розмарином | C26: 150 | D26: 25
B27: Кабачки жареные с помидорами и перцем | C27: 150 | D27: 20
B28: макароны отварные рататуй | C28: 150 | D28: 50
A29: ланч | B29: Каша перловая с овощами | C29: 150 | D29: 300
A30: ланч | B30: Капуста тушеная | C30: 150 | D30: 200
B31: Завтраки
B32: Каша рисовая молочная | C32: 200 | D32: 25
B33: Каша овсяная с яблоком постная | C33: 200 | D33: 25
B34: Запеканка творожная | C34: 100 | D34: 15
B35: Яйцо отварное | C35: 40 | D35: 10
B36: *Яичница глазунья 80 гр. | C36: 80 | D36: 30
B37: * Груша запеченная с медом и сыром | C37: 70 | D37: 10
B38: Пудинг творожный с изюмом | C38: 100 | D38: 7
B39: Омлет с ветчиной | C39: 105 | D39: 15
B40: Сосиски отварные | C40: 50 | D40: 10
B41: Сарделька отварная | C41: 100 | D41: 10
...

Sheet 23.10 понедельник 3 неделя
B1: 23.10.2023 понедельник
B2: Закуски и салаты | D2: кол-во
A3: ланч | B3: * Салат Щетка | C3: 120 | D3: 100
A4: ланч | B4: * Салат Столичный 120 гр. | C4: 120 | D4: 350
B5: -Салат из индейки с овощами 120 гр. | C5: 120 | D5: 20
B6: Сельдь под шубой | C6: 120 | D6: 15
B7: Салат Боярушка | C7: 120 | D7: 15
B8: Винегрет с маслом | C8: 120 | D8: 20
A9: Азия | B9: помидоры с красным луком | C9: 120 | D9: 40
B10: Первые блюда
B12: Борщ Сибирский с курой | C12: 250 | D12: 30
A13: Ланч | B13: * Рассольник Ленинградский с курицей 250/20 гр. | C13: 250/20 | D13: 300
A14: ланч | B14: * Суп-пюре овощной 250 гр. | C14: 250 | D14: 200
B16: Основные блюда
A17: Ланч | B17: люля из курицы замена на Поджарка из свинины в томатном соусе | C17: 100 | D17: 300
A18: ланч | B18: Горбуша по-Гречески | C18: 100 | D18: 200
B19: Индейка гриль | C19: 100 | D19: 30
B20: Плескавица на гриле | C20: 100 | D20: 15
B21: Свинина с грибами | C21: 100 | D21: 15
B22: Бефстроганов из говядины | C22: 75/50 | D22: 20
B23: Филе куриное в сырной корочке | C23: 100 | D23: 10
A24: Азия | B24: плов из курицы | C24: 250 | D24: 40
B25: Гарниры
A26: ланч | B26: Пюре картофельное | C26: 150 | D26: 300
A27: ланч | B27: Рис припущенный | C27: 150 | D27: 200
B28: Цветная капуста в сухарях | C28: 150 | D28: 25
B29: Фасоль стручковая с кунжутом | C29: 150 | D29: 20
B30: Овощи гриль | C30: 150 | D30: 20
B31: Спагетти с томатами, базиликом и чесноком | C31: 150 | D31: 50
B32: Завтраки
B33: Каша рисовая молочная | C33: 200 | D33: 20
B34: Каша геркулесовая постная | C34: 200 | D34: 20
B35: *Сырники из творога 100 гр | C35: 100 | D35: 15
B36: Яйцо отварное | C36: 40 | D36: 10
B37: Яичница глазунья с помидорами | C37: 100 | D37: 15
B38: *Омлет натуральный 105 | C38: 105 | D38: 15
B39: Сосиски отварные | C39: 50 | D39: 15
B40: Сарделька отварная | C40: 100 | D40: 15
B41: Рулет картофельный с овощами | C41: 150 | D41: 10
B42: Вареники в ассортименте (творог, капуста, картфель, грибы) | C42: 200 | D42: 15
...

Sheet вторник 24.10 3 неделя
B1: ВТОРНИК 24.10 | C1: выход
B2: Закуски и салаты
B3: Салат из крабовых палочек с огурцами | C3: 120 | D3: 15
B4: * Салат блинный с ветчиной 120 гр. | C4: 120 | D4: 15
B5: * Салат Азия 120 гр. | C5: 120 | D5: 15
B6: * Салат Здоровье 120 гр. | C6: 120 | D6: 15
A7: Ланч | B7: Салат Русский барин 120 гр. | C7: 120 | D7: 250
A8: Ланч | B8: * Салат весенний с овощами 120 гр. | C8: 120 | D8: 250
A9: азия | B9: * Салат домашний по-грузински со свежими овощами 120 гр. | D9: 40
B10: Первые блюда
B11: * Суп Пюре из тыквы | C11: 250/20 | D11: 30
A12: Ланч | B12: * Суп Гороховый с копченостями 250 гр. | C12: 250 | D12: 250
A13: Ланч | B13: Щи грибные со сметаной 250 гр. | C13: 250 | D13: 250
B14: Основные блюда
A15: Ланч | B15: * Филе куриное в соусе Терияки 80 гр. | C15: 80 | D15: 250
A16: Ланч | B16: * Голубцы Деревенские мясные 100/30 гр. | C16: 75/30 | D16: 250
B17: филе грудки гриль | C17: 110 | D17: 25
B18: Горбуша паровая с лимоном | C18: 100 | D18: 10
B19: Гуляш из говядины | C19: 75/50 | D19: 20
B20: * Филе куриное запеченное с кабачками и сыром 100 гр. | C20: 100 | D20: 20
B21: Свинина по-французски | C21: 100 | D21: 15
B22: котлета по киевки | C22: 120 | D22: 15
A23: АЗИЯ | B23: плов со свиноной | C23: 250 | D23: 40
B24: Гарниры
B25: Овощи Гриль | C25: 150 | D25: 35
A26: Ланч | B26: Фасоль красная отварная с перцем, заготовка | C26: 150 | D26: 150
A27: Ланч | B27: Макароны отварные 150 гр. | C27: 150 | D27: 350
B28: Пюре картофельное | C28: 150 | D28: 30
B29: тыква запеченая | C29: 150 | D29: 30
B30: Каша перловая с грибами и луком | C30: 150 | D30: 30
B31: Картофель Айдахо | C31: 150 | D31: 35
B32: Завтраки | D32: 0
B33: КАША кукурузная молочная | D33: 20
B34: КАША ПШЕНИЧНАЯ постная | D34: 20
B35: ГЛАЗУНЬЯ ИЗ 2-Х ЯИЦ | D35: 20
B36: ЯЙЦО ОТВАРНОЕ | D36: 10
B37: СОСИСКА ЖАРЕНАЯ | D37: 15
B38: Омлет натуральный | D38: 20
B39: Сырники | D39: 10
B40: блинчики с курицей | D40: 10
...

Sheet среда 25.10 3 неделя
B1: среда 25.10.2023
B2: Закуски и салаты
B3: Салат Зеленый | C3: 120 | D3: 30
B4: Салат по-Мексикански | C4: 120 | D4: 30
B5: Салат Русская красавица | C5: 120 | D5: 25
B6: * Салат из моркови с курицей, капустой и перцем 120 гр. | C6: 120 | D6: 20
A7: Ланч | B7: Салат Оливье с колбасой | C7: 120 | D7: 450
A8: Ланч | B8: * Салат Ассорти из морской капусты | C8: 120 | D8: 150
A9: АЗИЯ | B9: Салат капуста по-грузински | C9: 120 | D9: 50
B10: Первые блюда
A11: ланч | B11: Суп харчо с курицей | C11: 250 | D11: 400
A12: ланч | B12: * Суп овощной с зел. горошком с курицей 250 гр. | C12: 250/10 | D12: 200
B13: Суп-пюре овощной с цветной капустой | C13: 250 | D13: 30
B14: Основные блюда
A15: ланч | B15: * Поджарка из куриного филе 75/50 гр. | C15: 75/50 | D15: 250
A16: ланч | B16: * Котлета Росссийская | C16: 100 | D16: 200
A17: ланч | B17: Минтай жареный | C17: 100 | D17: 100
B18: * Гуляш по-Венгерски из говядины 75/50 гр. | C18: 75/50 | D18: 35
B19: Горбуша запеченная по-Русски | C19: 100 | D19: 20
B20: * Бифштекс с яйцом | C20: 100 | D20: 30
B21: Эскалоп Оригинальный | C21: 100 | D21: 30
B22: * Куриная грудка гриль 100 гр. | C22: 100 | D22: 30
A23: АЗИЯ | B23: лагман жареный | C23: 250 | D23: 50
B24: Гарниры
B25: Кус-кус с овощами | C25: 150 | D25: 30
B26: * Кабачки со сметаной и чесноком 150 гр. | C26: 150 | D26: 30
B27: Картофель запеченный с паприкой | C27: 150 | D27: 30
A28: ланч | B28: Каша гречневая рассыпчатая | C28: 150 | D28: 250
A29: ланч | B29: Картофель отварной с зеленью | C29: 150 | D29: 350
B30: Тыква запеченая | C30: 150 | D30: 30
B31: Овощи паровые капуста цв. Брокколи | C31: 150 | D31: 30
B32: Завтраки
B33: *Каша молочная 3 злака | C33: 200 | D33: 30
B34: Каша ячневая постная с фруктами | C34: 200 | D34: 30
B35: Пудинг творожный с бананом | C35: 130 | D35: 20
B36: Яйцо отварное | C36: 40 | D36: 10
B37: *Яичница глазунья 80 гр. | C37: 80 | D37: 30
B38: Омлет с зеленым луком | C38: 105 | D38: 30
B39: Сосиски отварные | C39: 50 | D39: 30
B40: Сарделька отварная | C40: 100 | D40: 15
...

Sheet четверг 26.10 3 неделя
B1: четверг 26.10
B2: Закуски и салаты | D2: кол-во
B3: Салат Вавилон | C3: 120 | D3: 20
B4: Салат Мадрид с курой копченой | C4: 120 | D4: 15
B5: * Салат Пекинский с курицей 120 гр. | C5: 120 | D5: 25
B6: * Салат Сибирский 120 гр. | C6: 120 | D6: 25
A7: ланч | B7: Салат Полтавский | C7: 120 | D7: 300
A8: ланч | B8: Салат Несвижский | C8: 120 | D8: 250
A9: Азия | B9: салат кимпаб | C9: 120 | D9: 35
B10: Первые блюда
B12: * Суп Грибной по-латвийски со сливками 250 гр. | C12: 250 | D12: 35
A13: Ланч | B13: Суп с рисовой лапшой | C13: 250 | D13: 200
A14: ланч | B14: *Борщ украинский 250/15 | C14: 250/15 | D14: 300
B16: Основные блюда
A17: ланч | B17: * Свинина Нежная 100 гр. | C17: 100 | D17: 375
A18: ланч | B18: Ежики в красном соусе | C18: 120/30 | D18: 100
A19: ланч | B19: Печень куринная с овощами | C19: 100 | D19: 150
B20: Плескавица на гриле | C20: 100 | D20: 25
B21: Филе горбуши запеченное с грибами и сыром | C21: 100 | D21: 15
B22: Индейка гриль | C22: 100 | D22: 15
B24: Говядина с грибами и овощами | C24: 100 | D24: 15
B25: Филе куриное Питерское с ветчиной | C25: 100 | D25: 25
A26: Азия | B26: Фунчоза с курицей вок | D26: 15
B27: Гарниры
A28: ланч | B28: Картофельное пюре | C28: 150 | D28: 300
A29: ланч | B29: Рис припущенный | C29: 150 | D29: 200
B30: Овощи гриль | C30: 150 | D30: 15
B31: Цветная капуста в сухарях | C31: 150 | D31: 25
B32: Макароны отварные с сыром | C32: 150 | D32: 50
B33: Гратен Дофинуа | C33: 150 | D33: 30
B34: Кабачки, баклажаны жареные с овощами | C34: 150 | D34: 25
B35: Завтраки
B36: Каша рисовая молочная | C36: 200 | D36: 30
B37: Каша геркулесовая постная | C37: 200 | D37: 20
B38: *Сырники из творога 100 гр | C38: 100 | D38: 20
B39: Яйцо отварное | C39: 40 | D39: 15
B40: * Драники картофельные с кабачками 100 гр. | C40: 100 | D40: 25
B41: Яичница глазунья с помидорами | C41: 100 | D41: 30
B42: * Запеканка творожная мраморная 100 гр. | C42: 100 | D42: 20
B43: *Омлет натуральный 105 | C43: 105 | D43: 30
...

Sheet пятница 27.10 3 неделя
B1: пятница 27.10
B2: Закуски и салаты
B3: Салат Амур с колбасой и майонезной заправкой 120 гр. | C3: 120 | D3: 20
B4: Салат из помидоров с брынзой и зеленой заправкой | C4: 120 | D4: 15
B5: Салат Фунчоза с курицей | C5: 120 | D5: 30
B6: Сельдь с картофелем и луком | C6: 120 | D6: 20
A7: ланч | B7: Салат Поло | C7: 120 | D7: 350
A8: ланч | B8: Салат Фантазия | C8: 120 | D8: 150
A9: Азия | B9: * Салат Чап-ча с болгарским перцем 120 гр. | C9: 120 | D9: 30
B10: Первые блюда
B11: * Суп шурпа с говядиной и овощами по-узбекски 250 гр. | C11: 250 | D11: 30
A12: ланч | B12: Щи грибоедовские с грибами | C12: 250/20 | D12: 250
A13: ланч | B13: * Токмач с курицей 250 гр. | C13: 250 | D13: 250
B15: Основные блюда
A16: ланч | B16: Тефтели мясные | C16: 100 | D16: 200
A17: ланч | B17: * Печень по-строгановски 75/50 гр. | C17: 75/50 | D17: 100
A18: ланч | B18: * Курица отварная 100 | C18: 100 | D18: 300
B19: * Азу из говядины 75/50 гр. | C19: 75/50 | D19: 15
B20: Бифштекс рубленый с яйцом | C20: 120 | D20: 20
B21: Филе горбуши запеченное с грибами и сыром | C21: 100 | D21: 15
B22: окунь жареный | C22: 100 | D22: 7
B23: Свинина запеченная с черносливом и сыром | C23: 100 | D23: 20
A24: Азия | B24: Плов с курицей | D24: 30
B25: Гарниры
B26: Картофель Айдахо | C26: 150 | D26: 30
B27: Морковь пряная с травами | C27: 150 | D27: 30
B28: Тыква запеченная с розмарином | C28: 150 | D28: 25
B29: Овощи гриль | C29: 150 | D29: 30
A30: ланч | B30: Капуста тушеная | C30: 150 | D30: 300
A31: ланч | B31: * Макароны отварные 150 гр. | C31: 150 | D31: 300
B32: * Каша гречневая с грибами 150 гр. | C32: 150 | D32: 30
B33: Завтраки
B34: Каша овсяная с яблоком постная | C34: 200 | D34: 20
B35: Каша рисовая молочная | C35: 200 | D35: 20
B36: Омлет с ветчиной | C36: 100 | D36: 20
B37: Глазунья | C37: 2 | D37: 40
B38: Яйцо отварное | D38: 10
B39: Сосиски отварные | D39: 15
B40: Горячий бутерброд с ветчиной | D40: 20
B41: Блинчики | D41: 15
...

Sheet понедельник 30.10 1 неделя
B1: понедельник 30/10
B3: * Салат Витаминка с яблоком 120 гр. | C3: 120 | D3: 30
B4: Салат Блинный с Ветчиной | C4: 120 | D4: 25
B5: Оливье с ветчиной | C5: 120 | D5: 25
B6: Винегрет | C6: 120 | D6: 20
A7: ланч | B7: Салат из брокколи с морковью и огурцами | C7: 120 | D7: 200
A8: ланч | B8: * Салат Казань с курицей 120 | C8: 120 | D8: 300
A9: азия | B9: капуста по-грузински | C9: 120 | D9: 40
B10: Первые блюда
A11: ланч | B11: * Борщ Кубанский с кабачками и курицей | C11: 250 | D11: 200
A12: ланч | B12: Рассольник с фасолью | C12: 250 | D12: 250
B13: * Суп-пюре из брокколи 250/10 гр. | C13: 250 | D13: 35
B14: Основные блюда
A15: ланч | B15: Свинина по-строгановски | C15: 100 | D15: 150
A16: ланч | B16: * Биточки по-белорусски 100 гр. | C16: 100 | D16: 100
A17: ланч | B17: Филе куриное с соусом карри | C17: 100 | D17: 300
B18: Говядина в кислосдадком соусе | C18: 75/50 | D18: 20
B19: Горбуша припущенная с лимоном | C19: 100 | D19: 30
B20: * Свинина Праздничная 100 гр. | C20: 100 | D20: 20
B21: *Котлета по киевски | C21: 100 | D21: 35
B22: Индейка гриль | C22: 100 | D22: 30
A23: азия | B23: плов с курицей | C23: 250 | D23: 40
B24: Гарниры
A25: ланч | B25: Рис припущенный | C25: 150 | D25: 150
A26: ланч | B26: Пюре картофельное | C26: 150 | D26: 350
B27: Булгур с овощами | C27: 150 | D27: 25
B28: Капуста тушеная с беконом | C28: 150 | D28: 25
B29: Картофель айдахо | C29: 150 | D29: 30
B30: Макароны отварные | C30: 150 | D30: 100
B31: Овощи гриль | C31: 150 | D31: 30
B32: завтрак
B33: *Каша молочная рисовая | C33: 200 | D33: 20
B34: Каша овсяная с яблоком постная | C34: 200 | D34: 20
B35: Кесадилья с ветчиной и овощами | C35: 100 | D35: 10
B36: глазунья из 2 яиц | C36: 80 | D36: 30
B37: яйцо отварное | C37: 1шт | D37: 10
B38: сосиска отварная | C38: 1 шт | D38: 10
B39: Сырники | D39: 10
B40: Сарделька отварная | C40: 100 | D40: 5
B41: * Запеканка из творога с курагой | C41: 100 | D41: 10
...

Sheet вторник 31.10 1 неделя
B1: ВТОРНИК 31.10 | C1: выход
B2: Закуски и салаты
B3: Салат из свеклы с черносливом | C3: 120 | D3: 20
B4: * Салат Азия 120 гр. | C4: 120 | D4: 25
B5: * Салат Чика с курицей,черносливом и огурцом 120гр | C5: 120 | D5: 25
B6: Салат Невеста | C6: 120 | D6: 25
A7: Ланч | B7: Салат Сельдь под шубой | C7: 120 | D7: 300
A8: Ланч | B8: Салат из китайской капусты с овощами | C8: 120 | D8: 200
A9: азия | B9: Салат из помидоров с красным луком | D9: 40
B10: Первые блюда
B11: Суп Гороховый с копченостями 250 гр. | C11: 250 | D11: 30
A12: Ланч | B12: Суп-лапша куриный | C12: 250/20 | D12: 250
A13: Ланч | B13: Суп-пюре сырный 250/10гр | C13: 250/10 | D13: 250
B16: Основные блюда
A17: ланч | B17: Люля кебаб из курицы с острым соусом | C17: 100/10 | D17: 220
A18: ланч | B18: минтай жареный | C18: 100 | D18: 100
A19: ланч | B19: Свинина в кисло-сладком соусе | C19: 75/30 | D19: 230
B20: Курица барбекю с кунжутом | C20: 100 | D20: 15
B21: Гуляш по-Венгерски из говядины | C21: 75/50 | D21: 15
B22: индейка гриль | C22: 100 | D22: 30
B23: Филе куриное запеченное с овощами и сыром моцарела | C23: 100 | D23: 15
B24: Котлета Обжорка | C24: 100 | D24: 15
B25: Филе горбуши припущенное с овощами | C25: 100 | D25: 15
A26: АЗИЯ | B26: СОБА С КУРИЦЕЙ | C26: 250 | D26: 40
B27: Гарниры
B29: Овощи Гриль | C29: 150 | D29: 35
A30: Ланч | B30: Каша гречневая рассыпчатая | C30: 150 | D30: 250
A31: Ланч | B31: Капуста тушеная | C31: 150 | D31: 250
B32: Макароны с томато и зеленью | C32: 150 | D32: 50
B33: * Рис по-вьетнамски 150 гр. | C33: 150 | D33: 20
B34: Кус-кус с овощами | C34: 150 | D34: 20
B35: Каша перловая с овощами | C35: 150 | D35: 20
B36: * Булгур по-Купечески 150 гр. | C36: 150 | D36: 20
B37: Завтраки
B38: * Каша ячневая молочная с цукатами | D38: 15
B39: Каша овсянная молочная с тыквой | D39: 15
B40: *Сырники из творога 100 гр | D40: 10
B41: *Сыр твердый 15 г | D41: 10
B42: Яйцо отварное | D42: 10
B43: Яичница глазунья с сыром | D43: 25
...

Sheet среда 11.11 1 неделя (2)
B1: среда 1/11/2023
B2: Закуски и салаты
A3: ланч | B3: =[1]Лист1!$B$1 -> Закуска свекольная с огурцом и яйцом | C3: 120 | D3: 150
A4: ланч | B4: =[1]Лист1!B2 -> Салат Шанхай с курицей | C4: =[1]Лист1!C2 -> 120 | D4: 350
B5: Салат Белый лебедь | C5: 120 | D5: 30
B6: * Салат из курицы и овощей с чили 120 гр. | C6: 120 | D6: 20
B7: * Салат с фунчозой и снежным крабом 120 гр. | C7: 120 | D7: 15
B8: Салат Нежность | C8: 120 | D8: 25
A9: АЗИЯ | B9: Салат домашний по-грузински со свежими овощами | C9: 120 | D9: 40
B10: Первые блюда
B12: * Уха Ростовская с горбушей 250 гр. | C12: 250 | D12: 30
A13: ланч | B13: =[1]Лист1!B3 -> Щи из квашеной капусты с индейкой | C13: =[1]Лист1!C3 -> 250 | D13: 250
A14: ланч | B14: =[1]Лист1!B4 -> Суп минестроне с фасолью | C14: =[1]Лист1!C4 -> 75 | D14: 250
B17: Основные блюда
A18: ланч | B18: Чахохбили из курицы | C18: =[1]Лист1!C5 -> 100 | D18: 230
A19: ланч | B19: Суфле из печени | C19: 100 | D19: 80
A20: ланч | B20: =[1]Лист1!B6 -> Горбуша жареная в яйце | C20: =[1]Лист1!C6 -> 90 | D20: 210
B21: Курица барбекю с кунжутом | C21: 150 | D21: 20
B22: Люля-кебаб из говядины с луком маринованным | C22: 100/20 | D22: 20
B23: филе куринное гриль | C23: 100 | D23: 25
B24: Бифштекс на гриле с сыром | C24: 100 | D24: 25
B25: Свинина запеченная с черносливом и сыром | C25: 100 | D25: 20
A26: АЗИЯ | B26: плов из свинины | C26: 250 | D26: 35
B27: Гарниры
A28: ланч | B28: =[1]Лист1!B7 -> Картофель жареный | C28: 150 | D28: 250
A29: ланч | B29: =[1]Лист1!B8 -> Спагетти отварные | C29: 150 | D29: 250
B30: Картофель запеченный со сметаной 150 гр. | C30: 150 | D30: 25
B31: Свекла тушеная со сметаной | C31: 150 | D31: 25
B32: Тыква запеченая | C32: 150 | D32: 25
B33: Перец с овощами | C33: 150 | D33: 25
B34: * Капуста цветная жареная в сухарях 150 гр. | C34: 150 | D34: 25
B35: Завтраки
B36: =[2]Лист1!A1 -> *Каша молочная пшенная | C36: =[2]Лист1!B1 -> 200 | D36: 25
B37: =[2]Лист1!A2 -> Каша рисовая с курагой молочная | C37: =[2]Лист1!B2 -> 200 | D37: 25
B38: =[2]Лист1!A3 -> Пудинг творожный с изюмом | C38: =[2]Лист1!B3 -> 100 | D38: 15
B39: =[2]Лист1!A5 -> Яйцо отварное | C39: =[2]Лист1!B5 -> 40 | D39: 10
B40: =[2]Лист1!A6 -> *Яичница глазунья 80 гр. | C40: =[2]Лист1!B6 -> 80 | D40: 20
B41: =[2]Лист1!A7 -> Омлет с зеленым горошком | C41: =[2]Лист1!B7 -> 100 | D41: 10
B42: =[2]Лист1!A8 -> Сосиски отварные | C42: =[2]Лист1!B8 -> 50 | D42: 15
B43: * Ветчина жареная 40 гр. | C43: 40 | D43: 15
...

Sheet 2.11 четверг 1 неделя (2)
A1: 1 неделя | B1: четверг 02.11
B2: Закуски и салаты
B3: Салат крабик | C3: 120 | D3: 30
B4: * Салат из стручковой фасоли с овощами 120 гр. | C4: 120 | D4: 15
B5: Сельдь с картофелем и луком | C5: 120 | D5: 20
B6: Салат из помидоров с брынзой и зеленой заправкой | C6: 120 | D6: 25
A7: ланч | B7: ='[3]Бизнес ланч '!D46 -> Салат с томатами и сельдереем | C7: ='[3]Бизнес ланч '!E46 -> 120 | D7: 170
A8: ланч | B8: Салат с ветчиной и овощами | C8: ='[3]Бизнес ланч '!E47 -> 120 | D8: 350
A9: Азия | B9: * Салат Чап-ча с болгарским перцем 120 гр. | C9: 120 | D9: 40
B10: Первые блюда
B11: * Суп Венгерский с мясом 250 гр. | C11: 250 | D11: 30
A12: ланч | B12: ='[3]Бизнес ланч '!D48 -> Гороховый с копченостями 250гр | C12: ='[3]Бизнес ланч '!E48 -> 250 | D12: 300
A13: ланч | B13: ='[3]Бизнес ланч '!D49 -> Суп-пюре Паприкаш | C13: ='[3]Бизнес ланч '!E49 -> 250 | D13: 200
B15: Основные блюда
B16: Филе куриное запеченное с ананасом | C16: 100 | D16: 30
B17: Говядина с грибами и овощами | C17: 100 | D17: 30
B18: Шашлык из свинины с овощами | C18: 100 | D18: 20
B19: * Куриные крылышки жаренные в арахисовом соусе по-сеульски 100 гр. | C19: 100 | D19: 15
B20: Горбуша запеченная с томатами | C20: 100 | D20: 30
A21: ланч | B21: Бифштекс по-Венгерски | C21: 100 | D21: 250
A22: ланч | B22: Печень Говяжья по-строгановски | C22: 75/50 | D22: 100
A23: ланч | B23: Курица жареная с аджикой (замена на биточки по-белорусски) | C23: 100 | D23: 170
A24: Азия | B24: Лагман Жареный | C24: 250 | D24: 40
B25: Гарниры
B26: Картофель Айдахо | C26: 150 | D26: 45
B27: Тыква запеченная с розмарином | C27: 150 | D27: 30
B28: Баклажаны в соевом соусе с чесноком и кунжутом | C28: 150 | D28: 20
B29: Рагу овощное | C29: 150 | D29: 30
A30: ланч | B30: Плов овощной | C30: 150 | D30: 250
A31: ланч | B31: Макароны отварные с соусом Песто | C31: 150 | D31: 250
B33: Завтраки
B34: Каша гречневая молочная | C34: 200 | D34: 20
B35: Каша ячневая постная с фруктами | C35: 200 | D35: 20
B36: *Сырники из творога 100 гр | C36: 100 | D36: 20
B37: Панкейки с бананом и ванильным соусом | C37: 100 | D37: 10
B38: * Оладьи из курицы с кукурузой и зеленью | C38: 100/30 гр. | D38: 10
B39: Яйцо отварное | C39: 40 | D39: 10
B40: Яичница глазунья с сосисками | C40: 100 | D40: 30
B41: Омлет с сыром | C41: 105 | D41: 20
B42: Сосиски отварные | C42: 50 | D42: 10
...

Sheet 3.11 пятница 1 неделя
B1: пятница 03.11
B2: Закуски и салаты | D2: кол-во
B3: * Салат Коул Слоу 120 гр. | C3: 120 | D3: 20
B4: Оливье с колбасой | C4: 120 | D4: 30
B5: * Салат Вдохновение (курица, ветчина) 120 гр. | C5: 120 | D5: 25
B6: * Салат из курицы с арахисом 120 гр. | C6: 120 | D6: 20
A7: Ланч | B7: Салат Овощной микс | C7: 120 | D7: 150
A8: ланч | B8: Салат Венеция с колбасой и огурцами | C8: 120 | D8: 350
A9: Азия | B9: Фунчоза с курицей | C9: 120 | D9: 40
B10: Первые блюда
B12: Суп-пюре Восточный с баклажанами | C12: 250 | D12: 30
A13: Ланч | B13: Солянка домашняя из птицы | C13: 250 | D13: 300
A14: ланч | B14: Суп-лапша по-казачьи | C14: 250 | D14: 200
B16: Основные блюда
B17: * Азу из говядины 75/50 гр. | C17: 100 | D17: 20
B18: филе куриное на гриле | C18: 100 | D18: 30
B19: Конвертик из свинины с овощами | C19: 100 | D19: 20
B20: Треска запеченная с помидорами и сладким перцем | C20: 100 | D20: 20
B21: Окунь жареный | C21: 100 | D21: 8
A22: Ланч | B22: * Печень куриная в сметанном соусе 75/50 гр. | C22: 75/50 | D22: 100
A23: Ланч | B23: Ежики в красном соусе | C23: 100/30 | D23: 200
A24: ланч | B24: * Поджарка из свинины в томатном соусе 75/30 гр. | C24: 100 | D24: 250
A25: Азия | B25: Плов с курицей | D25: 30
B26: Гарниры
A27: ланч | B27: Каша перловая с луком | C27: 150 | D27: 250
A28: ланч | B28: Рагу овощное | C28: 150 | D28: 250
B29: Спагетти отварные с сыром | C29: 150 | D29: 50
B30: овощи гриль | C30: 150 | D30: 25
B31: Картофель жареный с грибами | C31: 150 | D31: 40
B32: * Капуста цветная жареная в сухарях 150 гр. | C32: 150 | D32: 20
B33: Завтраки
B34: *Каша молочная 3 злака | C34: 200 | D34: 20
B35: Каша рисовая постная с бананом | C35: 200 | D35: 20
B36: Сырники с морковью | C36: 100 | D36: 15
B37: Кесадилья с ветчиной | C37: 15 | D37: 15
B38: Яйцо отварное | C38: 40 | D38: 10
B39: *Яичница глазунья 80 гр. | C39: 80 | D39: 20
B40: Омлет с ветчиной | C40: 105 | D40: 25
B41: Сосиски отварные | C41: 50 | D41: 20
B42: брускета с беконом | D42: 10
...

Sheet вторник 7.11 2 неделя 
B1: ВТОРНИК 7.11
B2: Закуски и салаты
B3: Салат из крабовых палочек с огурцами | C3: 120 | D3: 25
B4: * Салат Азия 120 гр. | C4: 120 | D4: 15
B5: Салат Ассорти из морской капусты | C5: 120 | D5: 25
B6: * Салат Звёздный 120 гр. | C6: 120 | D6: 20
A7: Ланч | B7: * Салат Чап-ча с болгарским перцем 120 гр. | C7: 120 | D7: 200
A8: Ланч | B8: * Салат колбасный 120 гр. | C8: 120 | D8: 300
A9: АЗИЯ | B9: * Салат домашний по-грузински со свежими овощами 120 гр. | D9: 20
B10: Первые блюда
B11: * Суп-крем из шампиньонов 250/10 гр. | C11: 250/10 | D11: 30
B12: * Борщ Сибирский с курой 250/20 гр. | C12: 250/20 | D12: 250
B13: * Суп Палиц 250 гр. | C13: 250 | D13: 200
B14: Основные блюда
B15: Филе Кеты в кляре | C15: 100 | D15: 15
B16: филе грудки гриль | C16: 110 | D16: 20
B17: Филе куриное запеченное с кабачками и сыром 100 гр. | C17: 100 | D17: 15
B18: Окунь жареный | C18: 100 | D18: 6
B19: Свинина по-французски | C19: 100 | D19: 10
B20: котлета по киевки | C20: 120 | D20: 30
A21: Ланч | B21: минтай жареный | C21: 100 | D21: 100
A22: Ланч | B22: Курица жареная с аджикой | C22: 100 | D22: 250
A23: Ланч | B23: * Поджарка из свинины в томатном соусе 75/30 гр. | C23: 75/30 | D23: 220
A24: АЗИЯ | B24: лагман жареный | C24: 250 | D24: 40
B25: Гарниры
B26: каша гречневая томленная | C26: 150 | D26: 100
B27: Картофель жареный с грибами | C27: 150 | D27: 30
B28: Тыква запеченая с розмарином | C28: 150 | D28: 20
B29: Баклажаны в соевом соусе с чесноком и кунжутом | C29: 150 | D29: 10
A30: Ланч | B30: Рагу овощное | C30: 150 | D30: 200
A31: Ланч | B31: Рис отварной с карри | C31: 150 | D31: 300
B32: Завтраки
B33: *Каша молочная 3 злака | D33: 20
B34: Каша ячневая постная с фруктами | D34: 20
B35: Жареная ветчина | C35: 40 | D35: 15
B36: Пудинг творожный с бананом | D36: 10
B37: Брускета с беконом | D37: 10
B38: Яйцо отварное | D38: 15
B39: *Яичница глазунья 80 гр. | D39: 20
B40: Омлет с зеленым луком | D40: 15
...

Sheet среда 8.11 2 неделя
B1: 08.11.2023 среда
B2: Закуски и салаты
B3: Салат Боярушка | C3: 120 | D3: 15
B4: Салат Белый лебедь | C4: 120 | D4: 20
B5: Салат Нежность | C5: 120 | D5: 20
B6: Салат Мимоза со скумбрией | C6: 120 | D6: 20
A7: ланч | B7: * Салат Журавушка 120 гр.(Капуста б/к, колбаса в/к, лук репчатый, майонез, специи ) | C7: 120 | D7: 250
A8: ланч | B8: Салат Фунчоза с курицей | C8: 120 | D8: 250
A9: АЗИЯ | B9: Салат из помидоров с красным луком | C9: 120 | D9: 40
B10: Первые блюда
B12: Суп Харчо с курицей | C12: 250 | D12: 30
A13: ланч | B13: * Солянка по-Волгоградски 250 гр. | C13: 250 | D13: 300
A14: ланч | B14: * Суп-пюре из зелёного горошка 250/10 гр. | C14: 250/10 | D14: 150
B17: Основные блюда
A18: ланч | B18: * Филе куриное по-строгановски 75/50 гр. | C18: 75/50 | D18: 200
A19: ланч | B19: Печень куриная в сметанном соусе | C19: 100 | D19: 100
A20: ланч | B20: Котлета пожарская | C20: 100 | D20: 250
B21: Филе куриное в сырной корочке | C21: 100 | D21: 30
B22: Горбуша под овощами | C22: 100 | D22: 20
B23: индейка гриль | C23: 100 | D23: 20
B24: Рулет мясной с зеленым луком и яйцом | C24: 100 | D24: 20
B25: Говядина с грибами и овощами | C25: 100 | D25: 15
B26: Шницель венский | C26: 100 | D26: 15
A27: АЗИЯ | B27: плов с курицей | C27: 250 | D27: 35
B28: Гарниры
A29: ланч | B29: Картофель отварной с зеленью | C29: 150 | D29: 300
A30: ланч | B30: Каша гречневая томленая | C30: 150 | D30: 150
B31: Кус-кус с овощами | C31: 150 | D31: 25
B32: * Кабачки со сметаной и чесноком 150 гр. | C32: 150 | D32: 20
B33: Макароны Рататуй | C33: 150 | D33: 100
B34: Тыква запеченая | C34: 150 | D34: 20
B35: Овощи гриль | C35: 150 | D35: 30
B36: Завтраки
B37: Каша рисовая молочная | C37: 200 | D37: 20
B38: Каша гречневая молочная | C38: 200 | D38: 15
B39: *Сырники из творога 100 гр | C39: 100 | D39: 10
B40: Яйцо отварное | C40: 40 | D40: 15
B41: Яичница глазунья с сыром | C41: 100 | D41: 25
B42: Омлет с грибами | C42: 105 | D42: 15
B43: Сосиски отварные | C43: 50 | D43: 15
...

Sheet четверг 09.11 2 неделя
B1: четверг 09.11.2023
B2: Закуски и салаты | D2: кол-во
B3: Салат Вавилон | C3: 120 | D3: 35
B4: Салат Мадрид с курой копченой | C4: 120 | D4: 30
B5: * Салат Цезарь с курицей 120 гр. | C5: 120 | D5: 25
B6: * Салат Сибирский 120 гр. | C6: 120 | D6: 25
A7: ланч | B7: * Салат Несвижский 120 гр. | C7: 120 | D7: 370
A8: ланч | B8: * Салат АВС и горошек 120 гр. | C8: 120 | D8: 150
A9: Азия | B9: Салат с фунчоза с курицей | C9: 120 | D9: 30
B10: Первые блюда
B12: Суп Английский куриный с плавленым сыром | C12: 250 | D12: 30
A13: Ланч | B13: * Суп картофельный с фасолью и курицей 250 гр. | C13: 250 | D13: 200
A14: ланч | B14: Суп Шурпа с курицей 250 гр. | C14: 250 | D14: 300
B16: Основные блюда
B17: Котлеты по-Хлыновски | C17: 100 | D17: 20
B18: Шашлычок из курицы с перцем | C18: 100 | D18: 20
B19: запеканка картофельная с мясом | C19: 200 | D19: 35
B20: Филе куры гриль | C20: 100 | D20: 20
B21: Говядина с черносливом | C21: 75/50 | D21: 20
B22: Горбуша запеченная с грибами | C22: 125 | D22: 20
A23: Ланч | B23: * Жаркое по-Краснодарски 250 гр. | C23: 250 | D23: 250
A24: Ланч | B24: Суфле из печени | C24: 100 | D24: 100
A25: ланч | B25: Чахохбили из курицы | C25: 100 | D25: 250
A26: азия ланч | B26: соба с курицей | D26: 25
B27: Гарниры
A28: Ланч | B28: Макароны отварные с сыром | D28: 250
B29: Каша перловая с овощами | C29: 150 | D29: 30
B30: Картофель запеченный с паприкой | C30: 150 | D30: 30
B31: Капуста цветная в сухарях | C31: 150 | D31: 25
B32: Гратен Дофинуа | C32: 150 | D32: 15
B33: Овощи гриль | C33: 150 | D33: 25
B34: Завтраки
B35: Каша манная молочная | C35: 200 | D35: 20
B36: Каша пшеничная постная | C36: 200 | D36: 20
B37: Запеканка творожная со смородиной | C37: 100 | D37: 10
B38: Яйцо отварное | C38: 40 | D38: 10
B39: *Яичница глазунья 80 гр. | C39: 80 | D39: 25
B40: *Омлет натуральный 105 | C40: 105 | D40: 15
B41: Сосиски отварные | C41: 50 | D41: 10
B42: Сарделька отварная | C42: 100 | D42: 10
...

Sheet 10.11 пятница 2 неделя
B1: пятница 10.11
B2: Закуски и салаты
B3: Салат Греческий | C3: 120 | D3: 15
B4: * Салат блинный с ветчиной 120 гр. | C4: 120 | D4: 20
A5: ланч | B5: Морковь по-корейски с огурцом | C5: 120 | D5: 170
A6: ланч | B6: * Салат Вдохновение (курица, ветчина) 120 гр. | C6: 120 | D6: 350
B7: * Салат Витаминка с яблоком 120 гр. | C7: 120 | D7: 15
B8: Салат крабик | C8: 120 | D8: 20
A9: АЗИЯ | B9: ачик-чучук | C9: 120 | D9: 30
B10: Первые блюда
B11: Суп-пюре овощной с цветной капустой | C11: 250/10 | D11: 30
A12: ланч | B12: * Суп Венгерский с мясом 250 гр. | C12: 250 | D12: 350
A13: ланч | B13: * Бульон куриный с куриными фрикадельками 250 гр. | C13: 250 | D13: 180
B14: Основные блюда
A16: ланч | B16: минтай жареный | C16: 100 | D16: 100
A17: ланч | B17: Бифштекс Провансаль | C17: 100 | D17: 210
A18: ланч | B18: Бедро куриное под тар-тар | C18: 120 | D18: 220
B19: Люля-кебаб из говядины с луком маринованным | C19: 100/30 | D19: 30
B20: Горбуша запеченная по-Русски | C20: 100 | D20: 10
B21: Треска запеченная с помидорами и сладким перцем | C21: 120 | D21: 20
B22: Эскалоп запеченный с ветчиной и сыром | C22: 100 | D22: 15
B23: Окунь жареный | C23: 100 | D23: 5
B24: * Куриная грудка гриль 100 гр. | C24: 100 | D24: 30
A25: АЗИЯ | B25: плов со свининой | D25: 30
B26: Гарниры
B27: Картофель жареный с грибами | C27: 150 | D27: 25
B28: Тыква запеченная с розмарином | C28: 150 | D28: 25
B29: макароны отварные рататуй | C29: 150 | D29: 25
B30: Кабачки жареные с помидорами и перцем | C30: 150 | D30: 20
B31: макароны отварные рататуй | C31: 150 | D31: 50
A32: ланч | B32: Каша перловая с овощами | C32: 150 | D32: 300
A33: ланч | B33: Капуста тушеная | C33: 150 | D33: 200
B34: Завтраки
B35: Каша рисовая молочная | C35: 200 | D35: 25
B36: Каша овсяная с яблоком постная | C36: 200 | D36: 25
B37: Запеканка творожная | C37: 100 | D37: 15
B38: Яйцо отварное | C38: 40 | D38: 10
B39: *Яичница глазунья 80 гр. | C39: 80 | D39: 30
B40: * Груша запеченная с медом и сыром | C40: 70 | D40: 10
B41: Пудинг творожный с изюмом | C41: 100 | D41: 7
...

Sheet 13.11 понедельник 3 неделя 
B1: 13.11.2023 понедельник
B2: Закуски и салаты | D2: кол-во
A3: ланч | B3: * Салат Щетка | C3: 120 | D3: 100
A4: ланч | B4: * Салат Столичный 120 гр. | C4: 120 | D4: 400
B5: -Салат из индейки с овощами 120 гр. | C5: 120 | D5: 20
B6: Сельдь под шубой | C6: 120 | D6: 15
B7: Салат Боярушка | C7: 120 | D7: 15
B8: Салат из кальмаров с крабовыми палочками и огурцом | C8: 120 | D8: 15
B9: Винегрет с маслом | C9: 120 | D9: 20
A10: Азия | B10: помидоры с красным луком | C10: 120 | D10: 40
B11: Первые блюда
B13: Борщ Сибирский с курой | C13: 250 | D13: 40
A14: Ланч | B14: Суп рыбный с треской | C14: 250/20 | D14: 250
A15: ланч | B15: * Суп-пюре овощной 250 гр. | C15: 250 | D15: 250
B17: Основные блюда
A18: Ланч | B18: Гуляш из свинины | C18: 100 | D18: 200
A19: Ланч | B19: * Тефтели мясные 100 гр. | C19: 100 | D19: 150
A20: ланч | B20: * Биточки по-белорусски 100 гр. | C20: 100 | D20: 200
B21: Индейка гриль | C21: 100 | D21: 30
B22: Плескавица на гриле | C22: 100 | D22: 15
B23: Свинина с грибами | C23: 100 | D23: 15
B24: Свинина пикантная | C24: 100 | D24: 15
B25: Бефстроганов из говядины | C25: 75/50 | D25: 20
B26: Бризоль из горбуши | C26: 100 | D26: 20
A27: Азия | B27: вок с фунчозой | C27: 250 | D27: 40
B28: Гарниры
A29: ланч | B29: Пюре картофельное | C29: 150 | D29: 300
A30: ланч | B30: Рис припущенный | C30: 150 | D30: 200
B31: Цветная капуста в сухарях | C31: 150 | D31: 25
B32: Фасоль стручковая с чесночком | C32: 150 | D32: 20
B33: Овощи гриль | C33: 150 | D33: 30
B34: Картофель запеченный с беконом и зеленью | C34: 150 | D34: 20
B35: Спагетти с томатами, базиликом и чесноком | C35: 150 | D35: 50
B36: Завтраки
B37: Каша рисовая молочная | C37: 200 | D37: 20
B38: Каша геркулесовая постная | C38: 200 | D38: 20
B39: *Сырники из творога 100 гр | C39: 100 | D39: 15
B40: Запеканка творожная с персиками | C40: 100 | D40: 10
B41: Оладьи с изюмом | C41: 100 | D41: 20
B42: Яйцо отварное | C42: 40 | D42: 10
...

Sheet вторник 14.11 3 неделя
B1: ВТОРНИК 14.11 | C1: выход
B2: Закуски и салаты
B3: Салат из свеклы с чесноком и сыром | C3: 120 | D3: 15
B4: Салат из крабовых палочек с огурцами | C4: 120 | D4: 15
B5: * Салат блинный с ветчиной 120 гр. | C5: 120 | D5: 15
B6: * Салат Азия 120 гр. | C6: 120 | D6: 15
B7: * Салат Здоровье 120 гр. | C7: 120 | D7: 15
A8: Ланч | B8: Салат Русский барин 120 гр. | C8: 120 | D8: 250
A9: Ланч | B9: * Салат весенний с овощами 120 гр. | C9: 120 | D9: 250
A10: АЗИЯ | B10: * Салат домашний по-грузински со свежими овощами 120 гр. | D10: 40
B11: Первые блюда
B12: * Суп Пюре из тыквы | C12: 250/20 | D12: 30
A13: Ланч | B13: * Суп Гороховый с копченостями 250 гр. | C13: 250 | D13: 300
A14: Ланч | B14: Щи грибные со сметаной 250 гр. | C14: 250 | D14: 200
B15: Основные блюда
A16: Ланч | B16: * Филе куриное в соусе Терияки 80 гр. | C16: 80 | D16: 250
A17: Ланч | B17: кета жареная 100 гр | C17: 100 | D17: 100
A18: Ланч | B18: * Голубцы Деревенские мясные 100/30 гр. | C18: 75/30 | D18: 150
B19: Индейка гриль | C19: 110 | D19: 25
B20: Горбуша запеченная с сыром и луком порей | C20: 100 | D20: 10
B21: Говядина в кисло-сладком соусе | C21: 75/50 | D21: 20
B22: * Филе куриное запеченное с кабачками и сыром 100 гр. | C22: 100 | D22: 20
B23: Свинина по-французски | C23: 100 | D23: 15
B24: котлета по киевки | C24: 120 | D24: 15
A25: АЗИЯ | B25: плов со свиноной | C25: 250 | D25: 40
B26: Гарниры
B27: Овощи Гриль | C27: 150 | D27: 35
A28: Ланч | B28: Фасоль красная отварная с перцем, заготовка | C28: 150 | D28: 150
A29: Ланч | B29: Макароны отварные 150 гр. | C29: 150 | D29: 350
B30: Пюре картофельное | C30: 150 | D30: 50
B31: Баклажаны в соевом соусе с чесноком и кунжутом | C31: 150 | D31: 20
B32: тыква запеченая | C32: 150 | D32: 25
B33: Каша перловая с грибами и луком | C33: 150 | D33: 30
B34: Картофель Айдахо | C34: 150 | D34: 35
B35: Завтраки | D35: 0
B36: КАША кукурузная молочная | D36: 20
B37: КАША ПШЕНИЧНАЯ постная | D37: 20
B38: ГЛАЗУНЬЯ ИЗ 2-Х ЯИЦ | D38: 20
B39: ЯЙЦО ОТВАРНОЕ | D39: 10
B40: СОСИСКА ЖАРЕНАЯ | D40: 15
...

Sheet среда 15.11 3 неделя
B1: среда 15.11.2023
B2: Закуски и салаты
B3: Салат Восхищение | C3: 120 | D3: 30
B4: Салат по-Мексикански | C4: 120 | D4: 30
B5: Салат Русская красавица | C5: 120 | D5: 25
B6: * Салат из моркови с курицей, капустой и перцем 120 гр. | C6: 120 | D6: 20
A7: Ланч | B7: Салат Оливье с колбасой | C7: 120 | D7: 370
A8: Ланч | B8: * Салат Ассорти из морской капусты | C8: 120 | D8: 150
A9: АЗИЯ | B9: Салат капуста по-грузински | C9: 120 | D9: 50
B10: Первые блюда
A11: ланч | B11: Суп харчо с курицей | C11: 250 | D11: 350
A12: ланч | B12: * Суп овощной с зел. горошком с курицей 250 гр. | C12: 250/10 | D12: 200
B13: * Уха Ростовская с горбушей 250 гр. | C13: 250 | D13: 30
B14: Основные блюда
A15: ланч | B15: * Поджарка из куриного филе 75/50 гр. | C15: 75/50 | D15: 250
A16: ланч | B16: * Котлета Росссийская | C16: 100 | D16: 200
A17: ланч | B17: Печень говяжья жареная с луком | C17: 100 | D17: 100
B18: * Гуляш по-Венгерски из говядины 75/50 гр. | C18: 75/50 | D18: 35
B19: Горбуша запеченная по-Русски | C19: 100 | D19: 20
B20: * Бифштекс с яйцом | C20: 100 | D20: 30
B21: Эскалоп Оригинальный | C21: 100 | D21: 30
B22: Свинина с грибами | C22: 100 | D22: 15
B23: * Куриная грудка гриль 100 гр. | C23: 100 | D23: 30
A24: АЗИЯ | B24: лагман жареный | C24: 250 | D24: 50
B25: Гарниры
B26: Кус-кус с овощами | C26: 150 | D26: 30
B27: * Кабачки со сметаной и чесноком 150 гр. | C27: 150 | D27: 30
B28: Картофель запеченный с паприкой | C28: 150 | D28: 30
A29: ланч | B29: Каша гречневая рассыпчатая | C29: 150 | D29: 250
A30: ланч | B30: Картофель отварной с зеленью | C30: 150 | D30: 350
B31: Тыква запеченая | C31: 150 | D31: 30
B32: Овощи паровые капуста цв. Брокколи | C32: 150 | D32: 30
B33: Завтраки
B34: *Каша молочная 3 злака | C34: 200 | D34: 20
B35: Каша ячневая постная с фруктами | C35: 200 | D35: 20
B36: Пудинг творожный с бананом | C36: 130 | D36: 20
B37: Яйцо отварное | C37: 40 | D37: 10
B38: Ветчина жаренная | C38: 50 | D38: 15
B39: Бекон жареный | C39: 40 | D39: 15
B40: *Яичница глазунья 80 гр. | C40: 80 | D40: 30
...

Sheet четверг 16.11 3 неделя 
B1: четверг 16.11
B2: Закуски и салаты | D2: кол-во
B3: Салат Вавилон | C3: 120 | D3: 25
B4: Салат Мадрид с курой копченой | C4: 120 | D4: 15
B5: * Салат Пекинский с курицей 120 гр. | C5: 120 | D5: 25
B6: * Салат Сибирский 120 гр. | C6: 120 | D6: 25
A7: ланч | B7: * Салат Фитнес 120 гр. | C7: 120 | D7: 300
A8: ланч | B8: Салат Застолье | C8: 120 | D8: 250
A9: Азия | B9: салат кимпаб | C9: 120 | D9: 35
B10: Первые блюда
B12: * Суп Грибной по-латвийски со сливками 250 гр. | C12: 250 | D12: 35
A13: Ланч | B13: Суп с рисовой лапшой | C13: 250 | D13: 250
A14: ланч | B14: *Борщ украинский 250/15 | C14: 250/15 | D14: 350
B16: Основные блюда
A17: ланч | B17: * Свинина Нежная 100 гр. | C17: 100 | D17: 375
A18: ланч | B18: Ежики в красном соусе | C18: 120/30 | D18: 100
A19: ланч | B19: Минтай жареный | C19: 100 | D19: 150
B20: Плескавица на гриле | C20: 100 | D20: 30
B21: Филе горбуши запеченное с грибами и сыром | C21: 100 | D21: 20
B22: Индейка гриль | C22: 100 | D22: 30
B23: Треска с грибами и брокколи | C23: 100 | D23: 15
B24: Говядина с грибами и овощами | C24: 100 | D24: 15
B25: Филе куриное Питерское с ветчиной | C25: 100 | D25: 25
A26: Азия | B26: Фунчоза с курицей вок | C26: 250 | D26: 35
B27: Гарниры
A28: ланч | B28: Картофель запеченный со сметаной | C28: 150 | D28: 350
A29: ланч | B29: Рис припущенный | C29: 150 | D29: 250
B30: Овощи гриль | C30: 150 | D30: 30
B31: Цветная капуста в сухарях | C31: 150 | D31: 25
B32: Макароны отварные с сыром | C32: 150 | D32: 50
B33: Гратен Дофинуа | C33: 150 | D33: 30
B34: Кабачки жареные с луком | C34: 150 | D34: 25
B35: Завтраки
B36: Каша рисовая молочная | C36: 200 | D36: 30
B37: Каша геркулесовая постная | C37: 200 | D37: 20
B38: *Сырники из творога 100 гр | C38: 100 | D38: 20
B39: Яйцо отварное | C39: 40 | D39: 15
B40: * Драники картофельные с кабачками 100 гр. | C40: 100 | D40: 25
B41: Яичница глазунья с помидорами | C41: 100 | D41: 30
B42: ветична жаренная 50 гр | C42: 50 | D42: 15
...

Sheet пятница 17.11 3 неделя
B1: пятница 27.10
B2: Закуски и салаты
B3: Салат Амур с колбасой и майонезной заправкой 120 гр. | C3: 120 | D3: 20
B4: Салат из помидоров с брынзой и зеленой заправкой | C4: 120 | D4: 20
B5: Салат Фунчоза с грибами | C5: 120 | D5: 30
B6: Сельдь с картофелем и луком | C6: 120 | D6: 20
A7: ланч | B7: Салат Поло | C7: 120 | D7: 350
A8: ланч | B8: Салат Фантазия | C8: 120 | D8: 170
A9: Азия | B9: * Салат Чап-ча с болгарским перцем 120 гр. | C9: 120 | D9: 30
B10: Первые блюда
B11: * Суп шурпа с говядиной и овощами по-узбекски 250 гр. | C11: 250 | D11: 30
A12: ланч | B12: Щи грибоедовские с грибами | C12: 250/20 | D12: 270
A13: ланч | B13: * Токмач с курицей 250 гр. | C13: 250 | D13: 270
B15: Основные блюда
A16: ланч | B16: Тефтели мясные | C16: 100 | D16: 200
A17: ланч | B17: * Печень по-строгановски 75/50 гр. | C17: 75/50 | D17: 100
A18: ланч | B18: * Курица отварная 100 | C18: 100 | D18: 300
B19: * Азу из говядины 75/50 гр. | C19: 75/50 | D19: 20
B20: Бифштекс рубленый с яйцом | C20: 120 | D20: 30
B21: Филе горбуши запеченное с грибами и сыром | C21: 100 | D21: 20
B22: филе куриное гриль | C22: 100 | D22: 30
B23: окунь жареный | C23: 100 | D23: 4
B24: Свинина запеченная с черносливом и сыром | C24: 100 | D24: 25
A25: Азия | B25: Плов с курицей | D25: 30
B26: Гарниры
B27: Картофель Айдахо | C27: 150 | D27: 30
B28: Морковь пряная с травами | C28: 150 | D28: 30
B29: Тыква запеченная с розмарином | C29: 150 | D29: 25
B30: * Пюре картофельное с морковью 150 гр. | C30: 150 | D30: 50
B31: Овощи гриль | C31: 150 | D31: 30
A32: ланч | B32: Капуста тушеная | C32: 150 | D32: 300
A33: ланч | B33: * Макароны отварные 150 гр. | C33: 150 | D33: 300
B34: * Каша гречневая с грибами 150 гр. | C34: 150 | D34: 30
B35: Завтраки
B36: Каша овсяная с яблоком постная | C36: 200 | D36: 20
B37: Каша рисовая молочная | C37: 200 | D37: 30
B38: Омлет с ветчиной | C38: 100 | D38: 20
